2021-09-06 02:04:18 ERROR (MainThread) [homeassistant.loader] Error loading custom_components.websocket_api. Make sure all dependencies are installed
Traceback (most recent call last):
  File "/srv/homeassistant/lib/python3.9/site-packages/homeassistant/loader.py", line 633, in _load_file
    module = importlib.import_module(path)
  File "/usr/local/lib/python3.9/importlib/__init__.py", line 127, in import_module
    return _bootstrap._gcd_import(name[level:], package, level)
  File "<frozen importlib._bootstrap>", line 1030, in _gcd_import
  File "<frozen importlib._bootstrap>", line 1007, in _find_and_load
  File "<frozen importlib._bootstrap>", line 972, in _find_and_load_unlocked
  File "<frozen importlib._bootstrap>", line 228, in _call_with_frames_removed
  File "<frozen importlib._bootstrap>", line 1030, in _gcd_import
  File "<frozen importlib._bootstrap>", line 1007, in _find_and_load
  File "<frozen importlib._bootstrap>", line 986, in _find_and_load_unlocked
  File "<frozen importlib._bootstrap>", line 680, in _load_unlocked
  File "<frozen importlib._bootstrap_external>", line 855, in exec_module
  File "<frozen importlib._bootstrap>", line 228, in _call_with_frames_removed
  File "/home/homeassistant/.homeassistant/custom_components/__init__.py", line 10, in <module>
    from .helpers.functions.configuration_schema import hacs_config_combined
  File "/home/homeassistant/.homeassistant/custom_components/helpers/__init__.py", line 2, in <module>
    from custom_components.hacs.helpers.methods import (
  File "/home/homeassistant/.homeassistant/custom_components/hacs/__init__.py", line 18, in <module>
    from .operational.setup import (
  File "/home/homeassistant/.homeassistant/custom_components/hacs/operational/setup.py", line 2, in <module>
    from aiogithubapi import AIOGitHubAPIException, GitHub, GitHubAPI
ImportError: cannot import name 'GitHubAPI' from 'aiogithubapi' (/srv/homeassistant/lib/python3.9/site-packages/aiogithubapi/__init__.py)
2021-09-06 02:04:19 WARNING (Recorder) [homeassistant.components.recorder.util] The system could not validate that the sqlite3 database at //home/homeassistant/.homeassistant/home-assistant_v2.db was shutdown cleanly
2021-09-06 02:04:20 WARNING (Recorder) [homeassistant.components.recorder.util] Ended unfinished session (id=20 from 2021-09-05 10:22:22.872481)
2021-09-06 02:04:23 ERROR (MainThread) [homeassistant.config] Invalid config for [group]: value should be a string for dictionary value @ data['group']['media_player']['entities']. Got None. (See /home/homeassistant/.homeassistant/configuration.yaml, line 130). Please check the docs at https://www.home-assistant.io/integrations/group
2021-09-06 02:04:23 ERROR (MainThread) [homeassistant.setup] Setup failed for group: Invalid config.
2021-09-06 02:04:35 WARNING (MainThread) [homeassistant.setup] Setup of input_select is taking over 10 seconds.
2021-09-06 02:04:35 WARNING (MainThread) [homeassistant.setup] Setup of counter is taking over 10 seconds.
2021-09-06 02:04:35 WARNING (MainThread) [homeassistant.setup] Setup of system_health is taking over 10 seconds.
2021-09-06 02:04:35 WARNING (MainThread) [homeassistant.setup] Setup of logbook is taking over 10 seconds.
2021-09-06 02:04:35 WARNING (MainThread) [homeassistant.setup] Setup of input_text is taking over 10 seconds.
2021-09-06 02:04:35 ERROR (MainThread) [homeassistant.setup] Setup failed for favicon: Integration not found.
2021-09-06 02:04:35 ERROR (MainThread) [homeassistant.setup] Setup failed for sonoff: Integration not found.
2021-09-06 02:04:35 ERROR (MainThread) [homeassistant.setup] Setup failed for media-source: Integration not found.
2021-09-06 02:04:35 ERROR (MainThread) [homeassistant.setup] Setup failed for media: Integration not found.
2021-09-06 02:04:35 ERROR (MainThread) [homeassistant.setup] Setup failed for auto_backup: Integration not found.
2021-09-06 02:04:38 ERROR (MainThread) [homeassistant.setup] Error during setup of component stream
Traceback (most recent call last):
  File "/srv/homeassistant/lib/python3.9/site-packages/homeassistant/setup.py", line 255, in _async_setup_component
    result = await task
  File "/srv/homeassistant/lib/python3.9/site-packages/homeassistant/components/stream/__init__.py", line 89, in async_setup
    from .recorder import async_setup_recorder
  File "/srv/homeassistant/lib/python3.9/site-packages/homeassistant/components/stream/recorder.py", line 10, in <module>
    import av
  File "/srv/homeassistant/lib/python3.9/site-packages/av/__init__.py", line 9, in <module>
    from av._core import time_base, pyav_version as __version__, library_versions
ImportError: /usr/lib/aarch64-linux-gnu/libgomp.so.1: cannot allocate memory in static TLS block
2021-09-06 02:04:39 ERROR (MainThread) [homeassistant.config] Invalid config for [automation]: [trigger] is an invalid option for [automation]. Check: automation->action->1->trigger. (See /home/homeassistant/.homeassistant/configuration.yaml, line 131). 
2021-09-06 02:04:39 ERROR (MainThread) [homeassistant.config] Invalid config for [automation]: required key not provided @ data['action']. Got None. (See /home/homeassistant/.homeassistant/configuration.yaml, line 131). 
2021-09-06 02:04:40 ERROR (SyncWorker_0) [homeassistant.components.hddtemp.sensor] HDDTemp is not available at localhost:7634
2021-09-06 02:04:41 ERROR (MainThread) [homeassistant.setup] Error during setup of component rpi_camera
Traceback (most recent call last):
  File "/srv/homeassistant/lib/python3.9/site-packages/homeassistant/setup.py", line 255, in _async_setup_component
    result = await task
  File "/usr/local/lib/python3.9/concurrent/futures/thread.py", line 52, in run
    result = self.fn(*self.args, **self.kwargs)
  File "/srv/homeassistant/lib/python3.9/site-packages/homeassistant/components/rpi_camera/__init__.py", line 68, in setup
    config_domain = config[DOMAIN]
KeyError: 'rpi_camera'
2021-09-06 02:04:41 ERROR (MainThread) [homeassistant.setup] Unable to prepare setup for platform rpi_camera.camera: Unable to set up component.
2021-09-06 02:04:41 ERROR (SyncWorker_4) [homeassistant.components.hddtemp.sensor] HDDTemp is not available at localhost:7634
2021-09-06 02:04:41 ERROR (MainThread) [homeassistant.config] Platform error: image_processing
Traceback (most recent call last):
  File "/srv/homeassistant/lib/python3.9/site-packages/homeassistant/config.py", line 891, in async_process_component_config
    platform = p_integration.get_platform(domain)
  File "/srv/homeassistant/lib/python3.9/site-packages/homeassistant/loader.py", line 524, in get_platform
    cache[full_name] = self._import_platform(platform_name)
  File "/srv/homeassistant/lib/python3.9/site-packages/homeassistant/loader.py", line 529, in _import_platform
    return importlib.import_module(f"{self.pkg_path}.{platform_name}")
  File "/usr/local/lib/python3.9/importlib/__init__.py", line 127, in import_module
    return _bootstrap._gcd_import(name[level:], package, level)
  File "<frozen importlib._bootstrap>", line 1030, in _gcd_import
  File "<frozen importlib._bootstrap>", line 1007, in _find_and_load
  File "<frozen importlib._bootstrap>", line 986, in _find_and_load_unlocked
  File "<frozen importlib._bootstrap>", line 680, in _load_unlocked
  File "<frozen importlib._bootstrap_external>", line 855, in exec_module
  File "<frozen importlib._bootstrap>", line 228, in _call_with_frames_removed
  File "/srv/homeassistant/lib/python3.9/site-packages/homeassistant/components/dlib_face_detect/image_processing.py", line 4, in <module>
    import face_recognition  # pylint: disable=import-error
  File "/srv/homeassistant/lib/python3.9/site-packages/face_recognition/__init__.py", line 7, in <module>
    from .api import load_image_file, face_locations, batch_face_locations, face_landmarks, face_encodings, compare_faces, face_distance
  File "/srv/homeassistant/lib/python3.9/site-packages/face_recognition/api.py", line 4, in <module>
    import dlib
  File "/srv/homeassistant/lib/python3.9/site-packages/dlib/__init__.py", line 19, in <module>
    from _dlib_pybind11 import *
ImportError: /srv/homeassistant/lib/python3.9/site-packages/_dlib_pybind11.cpython-39-aarch64-linux-gnu.so: undefined symbol: png_do_expand_palette_rgb8_neon
2021-09-06 02:04:42 ERROR (MainThread) [homeassistant.config] Platform error: image_processing - Integration '_AN_IMAGE_PROCESSING_PLATFORM_' not found.
2021-09-06 02:04:43 ERROR (MainThread) [homeassistant.components.device_tracker] Error setting up platform legacy trackr
Traceback (most recent call last):
  File "/srv/homeassistant/lib/python3.9/site-packages/homeassistant/components/device_tracker/legacy.py", line 255, in async_setup_legacy
    setup = await hass.async_add_executor_job(
  File "/usr/local/lib/python3.9/concurrent/futures/thread.py", line 52, in run
    result = self.fn(*self.args, **self.kwargs)
  File "/srv/homeassistant/lib/python3.9/site-packages/homeassistant/components/trackr/device_tracker.py", line 24, in setup_scanner
    TrackRDeviceScanner(hass, config, see)
  File "/srv/homeassistant/lib/python3.9/site-packages/homeassistant/components/trackr/device_tracker.py", line 35, in __init__
    self.api = trackrApiInterface(
  File "/srv/homeassistant/lib/python3.9/site-packages/pytrackr/api.py", line 30, in __init__
    self.authenticate()
  File "/srv/homeassistant/lib/python3.9/site-packages/pytrackr/api.py", line 74, in authenticate
    _LOGGER.error("Authentication request failed, please check credintials. " + status)
TypeError: can only concatenate str (not "int") to str
2021-09-06 02:04:59 WARNING (MainThread) [homeassistant.config_entries] Config entry 'Guest Remote' for broadlink integration not ready yet: [Errno -4000] Network timeout; Retrying in background
2021-09-06 02:05:02 WARNING (MainThread) [homeassistant.config_entries] Config entry 'FUJI XEROX DocuPrint CP116/119 w (44:57:9E)' for ipp integration not ready yet: Invalid response from API: Timeout occurred while connecting to IPP server.; Retrying in background
2021-09-06 02:05:12 ERROR (MainThread) [homeassistant.helpers.template] Template variable error: 'str object' has no attribute 'data' when rendering '{{ trigger.event.data.entity_id.split('_')[1] }} is'
2021-09-06 02:05:12 ERROR (MainThread) [homeassistant.components.automation.startup_notification] Startup Notification: Error executing script. Error for call_service at pos 1: Error rendering data template: UndefinedError: 'str object' has no attribute 'data'
2021-09-06 02:05:12 ERROR (MainThread) [homeassistant.components.automation.startup_notification] Error while executing automation automation.startup_notification: Error rendering data template: UndefinedError: 'str object' has no attribute 'data'
2021-09-06 02:05:15 ERROR (MainThread) [homeassistant] Error doing job: Task exception was never retrieved
Traceback (most recent call last):
  File "/srv/homeassistant/lib/python3.9/site-packages/homeassistant/components/homekit/__init__.py", line 719, in async_start
    if not await self._async_create_accessories():
  File "/srv/homeassistant/lib/python3.9/site-packages/homeassistant/components/homekit/__init__.py", line 848, in _async_create_accessories
    entity_states = await self.async_configure_accessories()
  File "/srv/homeassistant/lib/python3.9/site-packages/homeassistant/components/homekit/__init__.py", line 701, in async_configure_accessories
    await self._async_set_device_info_attributes(
  File "/srv/homeassistant/lib/python3.9/site-packages/homeassistant/components/homekit/__init__.py", line 942, in _async_set_device_info_attributes
    ent_cfg[ATTR_INTEGRATION] = integration.name
AttributeError: 'Event' object has no attribute 'name'
2021-09-06 02:05:15 ERROR (MainThread) [homeassistant.components.nmap_tracker] Nmap scanning failed: 'nmap program was not found in path. PATH is : /usr/local/sbin:/usr/local/bin:/usr/sbin:/usr/bin:/sbin:/bin'
2021-09-06 02:05:15 WARNING (MainThread) [homeassistant.components.homekit] The bridge Kitchen view has entity camera.camera_proxy_camera_kitchen_cam_profile_000. For best performance, and to prevent unexpected unavailability, create and pair a separate HomeKit instance in accessory mode for this entity
2021-09-06 02:05:15 WARNING (MainThread) [homeassistant.components.homekit] The bridge Kitchen view has entity camera.camera_proxy_camera_hall_cam. For best performance, and to prevent unexpected unavailability, create and pair a separate HomeKit instance in accessory mode for this entity
2021-09-06 02:05:15 WARNING (MainThread) [homeassistant.components.homekit] The bridge Kitchen view has entity camera.hall_cam. For best performance, and to prevent unexpected unavailability, create and pair a separate HomeKit instance in accessory mode for this entity
2021-09-06 02:05:15 WARNING (MainThread) [homeassistant.components.homekit] The bridge Kitchen view has entity camera.camera_proxy_camera_raspberry_pi_cam. For best performance, and to prevent unexpected unavailability, create and pair a separate HomeKit instance in accessory mode for this entity
2021-09-06 02:05:15 WARNING (MainThread) [homeassistant.components.homekit] The bridge Kitchen view has entity camera.vstarcam_profile_000. For best performance, and to prevent unexpected unavailability, create and pair a separate HomeKit instance in accessory mode for this entity
2021-09-06 02:05:24 ERROR (MainThread) [homeassistant.components.camera.img_util] Error loading libturbojpeg; Cameras may impact HomeKit performance
Traceback (most recent call last):
  File "/srv/homeassistant/lib/python3.9/site-packages/homeassistant/components/camera/img_util.py", line 96, in __init__
    TurboJPEGSingleton.__instance = TurboJPEG()
  File "/srv/homeassistant/lib/python3.9/site-packages/turbojpeg.py", line 148, in __init__
    self.__find_turbojpeg() if lib_path is None else lib_path)
  File "/srv/homeassistant/lib/python3.9/site-packages/turbojpeg.py", line 492, in __find_turbojpeg
    raise RuntimeError(
RuntimeError: Unable to locate turbojpeg library automatically. You may specify the turbojpeg library path manually.
e.g. jpeg = TurboJPEG(lib_path)
2021-09-06 02:05:57 ERROR (SyncWorker_8) [homeassistant.components.hddtemp.sensor] HDDTemp is not available at localhost:7634
2021-09-06 02:06:39 WARNING (MainThread) [homeassistant.components.ps4.media_player] PS4 could not be reached
2021-09-06 02:06:57 ERROR (SyncWorker_4) [homeassistant.components.hddtemp.sensor] HDDTemp is not available at localhost:7634
2021-09-06 02:07:55 WARNING (MainThread) [homeassistant.helpers.service] Unable to find referenced entities image_processing.door
2021-09-06 02:07:57 ERROR (SyncWorker_8) [homeassistant.components.hddtemp.sensor] HDDTemp is not available at localhost:7634
2021-09-06 02:07:59 ERROR (MainThread) [homeassistant.components.automation.push_ha_configuration_to_github_repo] push HA configuration to GitHub repo: Error executing script. Service not found for call_service at pos 1: Unable to find service hassio.addon_stdin
2021-09-06 02:07:59 ERROR (MainThread) [homeassistant.components.automation.push_ha_configuration_to_github_repo] Error while executing automation automation.push_ha_configuration_to_github_repo: Unable to find service hassio.addon_stdin
2021-09-06 02:08:15 ERROR (MainThread) [homeassistant.components.nmap_tracker] Nmap scanning failed: 'nmap program was not found in path. PATH is : /usr/local/sbin:/usr/local/bin:/usr/sbin:/usr/bin:/sbin:/bin'
2021-09-06 02:08:57 ERROR (SyncWorker_2) [homeassistant.components.hddtemp.sensor] HDDTemp is not available at localhost:7634
2021-09-06 02:09:09 WARNING (MainThread) [homeassistant.components.ps4.media_player] PS4 could not be reached
2021-09-06 02:09:57 ERROR (SyncWorker_2) [homeassistant.components.hddtemp.sensor] HDDTemp is not available at localhost:7634
2021-09-06 02:10:57 ERROR (SyncWorker_5) [homeassistant.components.hddtemp.sensor] HDDTemp is not available at localhost:7634
2021-09-06 02:11:18 ERROR (MainThread) [homeassistant.components.nmap_tracker] Nmap scanning failed: 'nmap program was not found in path. PATH is : /usr/local/sbin:/usr/local/bin:/usr/sbin:/usr/bin:/sbin:/bin'
